  1%|█▌                                                                                                                                | 10/804 [00:44<57:09,  4.32s/it]2025-01-07 11:09:48,129 [ERROR] Training failed
{'loss': 11.4592, 'grad_norm': 3.1482675075531006, 'learning_rate': 6.17283950617284e-07, 'epoch': 0.04}
Traceback (most recent call last):██████████████████████████████████████████████████████████████████████████████████████████████████████| 13/13 [00:02<00:00,  5.94it/s]
  File "/home/zahemen/projects/dl-lib/DocAnalyzerAI/src/main/train_finbot_qlora.py", line 344, in train
    trainer.train()
  File "/home/zahemen/miniconda3/envs/transformer_LM/lib/python3.11/site-packages/transformers/trainer.py", line 2052, in train
    return inner_training_loop(
           ^^^^^^^^^^^^^^^^^^^^
  File "/home/zahemen/miniconda3/envs/transformer_LM/lib/python3.11/site-packages/transformers/trainer.py", line 2467, in _inner_training_loop
    self._maybe_log_save_evaluate(tr_loss, grad_norm, model, trial, epoch, ignore_keys_for_eval)
  File "/home/zahemen/miniconda3/envs/transformer_LM/lib/python3.11/site-packages/transformers/trainer.py", line 2915, in _maybe_log_save_evaluate
    metrics = self._evaluate(trial, ignore_keys_for_eval)
              ^^^^^^^^^^^^^^^^^^^^^^^^^^^^^^^^^^^^^^^^^^^
  File "/home/zahemen/miniconda3/envs/transformer_LM/lib/python3.11/site-packages/transformers/trainer.py", line 2872, in _evaluate
    metrics = self.evaluate(ignore_keys=ignore_keys_for_eval)
              ^^^^^^^^^^^^^^^^^^^^^^^^^^^^^^^^^^^^^^^^^^^^^^^
  File "/home/zahemen/miniconda3/envs/transformer_LM/lib/python3.11/site-packages/transformers/trainer.py", line 3868, in evaluate
    output = eval_loop(
             ^^^^^^^^^^
  File "/home/zahemen/miniconda3/envs/transformer_LM/lib/python3.11/site-packages/transformers/trainer.py", line 4160, in evaluation_loop
    metrics = self.compute_metrics(EvalPrediction(predictions=all_preds, label_ids=all_labels))
              ^^^^^^^^^^^^^^^^^^^^^^^^^^^^^^^^^^^^^^^^^^^^^^^^^^^^^^^^^^^^^^^^^^^^^^^^^^^^^^^^^
  File "/home/zahemen/projects/dl-lib/DocAnalyzerAI/src/main/train_finbot_qlora.py", line 271, in compute_metrics
    preds = preds.tolist()
            ^^^^^^^^^^^^
AttributeError: 'tuple' object has no attribute 'tolist'
2025-01-07 11:09:48,130 [ERROR] Training failed: 'tuple' object has no attribute 'tolist'
Traceback (most recent call last):
  File "/home/zahemen/projects/dl-lib/DocAnalyzerAI/src/main/train_finbot_qlora.py", line 344, in train
    trainer.train()
  File "/home/zahemen/miniconda3/envs/transformer_LM/lib/python3.11/site-packages/transformers/trainer.py", line 2052, in train
    return inner_training_loop(
           ^^^^^^^^^^^^^^^^^^^^
  File "/home/zahemen/miniconda3/envs/transformer_LM/lib/python3.11/site-packages/transformers/trainer.py", line 2467, in _inner_training_loop
    self._maybe_log_save_evaluate(tr_loss, grad_norm, model, trial, epoch, ignore_keys_for_eval)
  File "/home/zahemen/miniconda3/envs/transformer_LM/lib/python3.11/site-packages/transformers/trainer.py", line 2915, in _maybe_log_save_evaluate
    metrics = self._evaluate(trial, ignore_keys_for_eval)
              ^^^^^^^^^^^^^^^^^^^^^^^^^^^^^^^^^^^^^^^^^^^
  File "/home/zahemen/miniconda3/envs/transformer_LM/lib/python3.11/site-packages/transformers/trainer.py", line 2872, in _evaluate
    metrics = self.evaluate(ignore_keys=ignore_keys_for_eval)
              ^^^^^^^^^^^^^^^^^^^^^^^^^^^^^^^^^^^^^^^^^^^^^^^
  File "/home/zahemen/miniconda3/envs/transformer_LM/lib/python3.11/site-packages/transformers/trainer.py", line 3868, in evaluate
    output = eval_loop(
             ^^^^^^^^^^
  File "/home/zahemen/miniconda3/envs/transformer_LM/lib/python3.11/site-packages/transformers/trainer.py", line 4160, in evaluation_loop
    metrics = self.compute_metrics(EvalPrediction(predictions=all_preds, label_ids=all_labels))
              ^^^^^^^^^^^^^^^^^^^^^^^^^^^^^^^^^^^^^^^^^^^^^^^^^^^^^^^^^^^^^^^^^^^^^^^^^^^^^^^^^
  File "/home/zahemen/projects/dl-lib/DocAnalyzerAI/src/main/train_finbot_qlora.py", line 271, in compute_metrics
    preds = preds.tolist()
            ^^^^^^^^^^^^
AttributeError: 'tuple' object has no attribute 'tolist'
2025-01-07 11:09:48,327 [ERROR] Script failed: 'tuple' object has no attribute 'tolist'
Traceback (most recent call last):
  File "/home/zahemen/projects/dl-lib/DocAnalyzerAI/src/main/train_finbot_qlora.py", line 376, in <module>
    train()
  File "/home/zahemen/projects/dl-lib/DocAnalyzerAI/src/main/train_finbot_qlora.py", line 344, in train
    trainer.train()
  File "/home/zahemen/miniconda3/envs/transformer_LM/lib/python3.11/site-packages/transformers/trainer.py", line 2052, in train
    return inner_training_loop(
           ^^^^^^^^^^^^^^^^^^^^
  File "/home/zahemen/miniconda3/envs/transformer_LM/lib/python3.11/site-packages/transformers/trainer.py", line 2467, in _inner_training_loop
    self._maybe_log_save_evaluate(tr_loss, grad_norm, model, trial, epoch, ignore_keys_for_eval)
  File "/home/zahemen/miniconda3/envs/transformer_LM/lib/python3.11/site-packages/transformers/trainer.py", line 2915, in _maybe_log_save_evaluate
    metrics = self._evaluate(trial, ignore_keys_for_eval)
              ^^^^^^^^^^^^^^^^^^^^^^^^^^^^^^^^^^^^^^^^^^^
  File "/home/zahemen/miniconda3/envs/transformer_LM/lib/python3.11/site-packages/transformers/trainer.py", line 2872, in _evaluate
    metrics = self.evaluate(ignore_keys=ignore_keys_for_eval)
              ^^^^^^^^^^^^^^^^^^^^^^^^^^^^^^^^^^^^^^^^^^^^^^^
  File "/home/zahemen/miniconda3/envs/transformer_LM/lib/python3.11/site-packages/transformers/trainer.py", line 3868, in evaluate
    output = eval_loop(
             ^^^^^^^^^^
  File "/home/zahemen/miniconda3/envs/transformer_LM/lib/python3.11/site-packages/transformers/trainer.py", line 4160, in evaluation_loop
    metrics = self.compute_metrics(EvalPrediction(predictions=all_preds, label_ids=all_labels))
              ^^^^^^^^^^^^^^^^^^^^^^^^^^^^^^^^^^^^^^^^^^^^^^^^^^^^^^^^^^^^^^^^^^^^^^^^^^^^^^^^^
  File "/home/zahemen/projects/dl-lib/DocAnalyzerAI/src/main/train_finbot_qlora.py", line 271, in compute_metrics
    preds = preds.tolist()
            ^^^^^^^^^^^^
AttributeError: 'tuple' object has no attribute 'tolist'
Traceback (most recent call last):
  File "/home/zahemen/projects/dl-lib/DocAnalyzerAI/src/main/train_finbot_qlora.py", line 376, in <module>
    train()
  File "/home/zahemen/projects/dl-lib/DocAnalyzerAI/src/main/train_finbot_qlora.py", line 344, in train
    trainer.train()
  File "/home/zahemen/miniconda3/envs/transformer_LM/lib/python3.11/site-packages/transformers/trainer.py", line 2052, in train
    return inner_training_loop(
           ^^^^^^^^^^^^^^^^^^^^
  File "/home/zahemen/miniconda3/envs/transformer_LM/lib/python3.11/site-packages/transformers/trainer.py", line 2467, in _inner_training_loop
    self._maybe_log_save_evaluate(tr_loss, grad_norm, model, trial, epoch, ignore_keys_for_eval)
  File "/home/zahemen/miniconda3/envs/transformer_LM/lib/python3.11/site-packages/transformers/trainer.py", line 2915, in _maybe_log_save_evaluate
    metrics = self._evaluate(trial, ignore_keys_for_eval)
              ^^^^^^^^^^^^^^^^^^^^^^^^^^^^^^^^^^^^^^^^^^^
  File "/home/zahemen/miniconda3/envs/transformer_LM/lib/python3.11/site-packages/transformers/trainer.py", line 2872, in _evaluate
    metrics = self.evaluate(ignore_keys=ignore_keys_for_eval)
              ^^^^^^^^^^^^^^^^^^^^^^^^^^^^^^^^^^^^^^^^^^^^^^^
  File "/home/zahemen/miniconda3/envs/transformer_LM/lib/python3.11/site-packages/transformers/trainer.py", line 3868, in evaluate
    output = eval_loop(
             ^^^^^^^^^^
  File "/home/zahemen/miniconda3/envs/transformer_LM/lib/python3.11/site-packages/transformers/trainer.py", line 4160, in evaluation_loop
    metrics = self.compute_metrics(EvalPrediction(predictions=all_preds, label_ids=all_labels))
              ^^^^^^^^^^^^^^^^^^^^^^^^^^^^^^^^^^^^^^^^^^^^^^^^^^^^^^^^^^^^^^^^^^^^^^^^^^^^^^^^^
  File "/home/zahemen/projects/dl-lib/DocAnalyzerAI/src/main/train_finbot_qlora.py", line 271, in compute_metrics
    preds = preds.tolist()
            ^^^^^^^^^^^^
AttributeError: 'tuple' object has no attribute 'tolist'
