  0%|                                                                                                                                                     | 0/110 [00:00<?, ?it/s]2024-12-30 21:06:38,231 [ERROR] Training failed: QuantizedLoRATrainer.compute_loss() got an unexpected keyword argument 'num_items_in_batch'
Traceback (most recent call last):
  File "/home/zahemen/projects/dl-lib/DocAnalyzerAI/src/train_finbot_quantized.py", line 309, in train_quantized
    trainer.train()
  File "/home/zahemen/miniconda3/envs/transformer_env/lib/python3.11/site-packages/transformers/trainer.py", line 2164, in train
    return inner_training_loop(
           ^^^^^^^^^^^^^^^^^^^^
  File "/home/zahemen/miniconda3/envs/transformer_env/lib/python3.11/site-packages/transformers/trainer.py", line 2524, in _inner_training_loop
    tr_loss_step = self.training_step(model, inputs, num_items_in_batch)
                   ^^^^^^^^^^^^^^^^^^^^^^^^^^^^^^^^^^^^^^^^^^^^^^^^^^^^^
  File "/home/zahemen/miniconda3/envs/transformer_env/lib/python3.11/site-packages/transformers/trainer.py", line 3654, in training_step
    loss = self.compute_loss(model, inputs, num_items_in_batch=num_items_in_batch)
           ^^^^^^^^^^^^^^^^^^^^^^^^^^^^^^^^^^^^^^^^^^^^^^^^^^^^^^^^^^^^^^^^^^^^^^^
TypeError: QuantizedLoRATrainer.compute_loss() got an unexpected keyword argument 'num_items_in_batch'
2024-12-30 21:06:38,372 [ERROR] Script failed: QuantizedLoRATrainer.compute_loss() got an unexpected keyword argument 'num_items_in_batch'
Traceback (most recent call last):
  File "/home/zahemen/projects/dl-lib/DocAnalyzerAI/src/train_finbot_quantized.py", line 349, in <module>
    train_quantized()
  File "/home/zahemen/projects/dl-lib/DocAnalyzerAI/src/train_finbot_quantized.py", line 309, in train_quantized
    trainer.train()
  File "/home/zahemen/miniconda3/envs/transformer_env/lib/python3.11/site-packages/transformers/trainer.py", line 2164, in train
    return inner_training_loop(
           ^^^^^^^^^^^^^^^^^^^^
  File "/home/zahemen/miniconda3/envs/transformer_env/lib/python3.11/site-packages/transformers/trainer.py", line 2524, in _inner_training_loop
    tr_loss_step = self.training_step(model, inputs, num_items_in_batch)
                   ^^^^^^^^^^^^^^^^^^^^^^^^^^^^^^^^^^^^^^^^^^^^^^^^^^^^^
  File "/home/zahemen/miniconda3/envs/transformer_env/lib/python3.11/site-packages/transformers/trainer.py", line 3654, in training_step
    loss = self.compute_loss(model, inputs, num_items_in_batch=num_items_in_batch)
           ^^^^^^^^^^^^^^^^^^^^^^^^^^^^^^^^^^^^^^^^^^^^^^^^^^^^^^^^^^^^^^^^^^^^^^^
TypeError: QuantizedLoRATrainer.compute_loss() got an unexpected keyword argument 'num_items_in_batch'
Traceback (most recent call last):
  File "/home/zahemen/projects/dl-lib/DocAnalyzerAI/src/train_finbot_quantized.py", line 349, in <module>
    train_quantized()
  File "/home/zahemen/projects/dl-lib/DocAnalyzerAI/src/train_finbot_quantized.py", line 309, in train_quantized
    trainer.train()
  File "/home/zahemen/miniconda3/envs/transformer_env/lib/python3.11/site-packages/transformers/trainer.py", line 2164, in train
    return inner_training_loop(
           ^^^^^^^^^^^^^^^^^^^^
  File "/home/zahemen/miniconda3/envs/transformer_env/lib/python3.11/site-packages/transformers/trainer.py", line 2524, in _inner_training_loop
    tr_loss_step = self.training_step(model, inputs, num_items_in_batch)
                   ^^^^^^^^^^^^^^^^^^^^^^^^^^^^^^^^^^^^^^^^^^^^^^^^^^^^^
  File "/home/zahemen/miniconda3/envs/transformer_env/lib/python3.11/site-packages/transformers/trainer.py", line 3654, in training_step
    loss = self.compute_loss(model, inputs, num_items_in_batch=num_items_in_batch)
           ^^^^^^^^^^^^^^^^^^^^^^^^^^^^^^^^^^^^^^^^^^^^^^^^^^^^^^^^^^^^^^^^^^^^^^^
TypeError: QuantizedLoRATrainer.compute_loss() got an unexpected keyword argument 'num_items_in_batch'
