2024-12-28 20:25:00,328 INFO    MainThread:90855 [wandb_setup.py:_flush():68] Current SDK version is 0.19.1
2024-12-28 20:25:00,328 INFO    MainThread:90855 [wandb_setup.py:_flush():68] Configure stats pid to 90855
2024-12-28 20:25:00,328 INFO    MainThread:90855 [wandb_setup.py:_flush():68] Loading settings from /home/zahemen/.config/wandb/settings
2024-12-28 20:25:00,328 INFO    MainThread:90855 [wandb_setup.py:_flush():68] Loading settings from /home/zahemen/projects/dl-lib/DocAnalyzerAI/wandb/settings
2024-12-28 20:25:00,328 INFO    MainThread:90855 [wandb_setup.py:_flush():68] Loading settings from environment variables
2024-12-28 20:25:00,328 INFO    MainThread:90855 [wandb_init.py:_log_setup():528] Logging user logs to /home/zahemen/projects/dl-lib/DocAnalyzerAI/wandb/run-20241228_202500-udcv1pfh/logs/debug.log
2024-12-28 20:25:00,328 INFO    MainThread:90855 [wandb_init.py:_log_setup():529] Logging internal logs to /home/zahemen/projects/dl-lib/DocAnalyzerAI/wandb/run-20241228_202500-udcv1pfh/logs/debug-internal.log
2024-12-28 20:25:00,328 INFO    MainThread:90855 [wandb_init.py:init():644] calling init triggers
2024-12-28 20:25:00,328 INFO    MainThread:90855 [wandb_init.py:init():650] wandb.init called with sweep_config: {}
config: {}
2024-12-28 20:25:00,328 INFO    MainThread:90855 [wandb_init.py:init():680] starting backend
2024-12-28 20:25:00,328 INFO    MainThread:90855 [wandb_init.py:init():684] sending inform_init request
2024-12-28 20:25:00,331 INFO    MainThread:90855 [backend.py:_multiprocessing_setup():104] multiprocessing start_methods=fork,spawn,forkserver, using: spawn
2024-12-28 20:25:00,332 INFO    MainThread:90855 [wandb_init.py:init():697] backend started and connected
2024-12-28 20:25:00,334 INFO    MainThread:90855 [wandb_init.py:init():790] updated telemetry
2024-12-28 20:25:00,337 INFO    MainThread:90855 [wandb_init.py:init():822] communicating run to backend with 90.0 second timeout
2024-12-28 20:25:47,997 INFO    Thread-3 (wrapped_target):90855 [retry.py:__call__():172] Retry attempt failed:
Traceback (most recent call last):
  File "/home/zahemen/miniconda3/envs/transformer_env/lib/python3.11/site-packages/urllib3/connectionpool.py", line 466, in _make_request
    self._validate_conn(conn)
  File "/home/zahemen/miniconda3/envs/transformer_env/lib/python3.11/site-packages/urllib3/connectionpool.py", line 1095, in _validate_conn
    conn.connect()
  File "/home/zahemen/miniconda3/envs/transformer_env/lib/python3.11/site-packages/urllib3/connection.py", line 730, in connect
    sock_and_verified = _ssl_wrap_socket_and_match_hostname(
                        ^^^^^^^^^^^^^^^^^^^^^^^^^^^^^^^^^^^^
  File "/home/zahemen/miniconda3/envs/transformer_env/lib/python3.11/site-packages/urllib3/connection.py", line 909, in _ssl_wrap_socket_and_match_hostname
    ssl_sock = ssl_wrap_socket(
               ^^^^^^^^^^^^^^^^
  File "/home/zahemen/miniconda3/envs/transformer_env/lib/python3.11/site-packages/urllib3/util/ssl_.py", line 469, in ssl_wrap_socket
    ssl_sock = _ssl_wrap_socket_impl(sock, context, tls_in_tls, server_hostname)
               ^^^^^^^^^^^^^^^^^^^^^^^^^^^^^^^^^^^^^^^^^^^^^^^^^^^^^^^^^^^^^^^^^
  File "/home/zahemen/miniconda3/envs/transformer_env/lib/python3.11/site-packages/urllib3/util/ssl_.py", line 513, in _ssl_wrap_socket_impl
    return ssl_context.wrap_socket(sock, server_hostname=server_hostname)
           ^^^^^^^^^^^^^^^^^^^^^^^^^^^^^^^^^^^^^^^^^^^^^^^^^^^^^^^^^^^^^^
  File "/home/zahemen/miniconda3/envs/transformer_env/lib/python3.11/ssl.py", line 517, in wrap_socket
    return self.sslsocket_class._create(
           ^^^^^^^^^^^^^^^^^^^^^^^^^^^^^
  File "/home/zahemen/miniconda3/envs/transformer_env/lib/python3.11/ssl.py", line 1104, in _create
    self.do_handshake()
  File "/home/zahemen/miniconda3/envs/transformer_env/lib/python3.11/ssl.py", line 1382, in do_handshake
    self._sslobj.do_handshake()
ssl.SSLEOFError: [SSL: UNEXPECTED_EOF_WHILE_READING] EOF occurred in violation of protocol (_ssl.c:1006)

During handling of the above exception, another exception occurred:

Traceback (most recent call last):
  File "/home/zahemen/miniconda3/envs/transformer_env/lib/python3.11/site-packages/urllib3/connectionpool.py", line 789, in urlopen
    response = self._make_request(
               ^^^^^^^^^^^^^^^^^^^
  File "/home/zahemen/miniconda3/envs/transformer_env/lib/python3.11/site-packages/urllib3/connectionpool.py", line 490, in _make_request
    raise new_e
urllib3.exceptions.SSLError: [SSL: UNEXPECTED_EOF_WHILE_READING] EOF occurred in violation of protocol (_ssl.c:1006)

The above exception was the direct cause of the following exception:

Traceback (most recent call last):
  File "/home/zahemen/miniconda3/envs/transformer_env/lib/python3.11/site-packages/requests/adapters.py", line 667, in send
    resp = conn.urlopen(
           ^^^^^^^^^^^^^
  File "/home/zahemen/miniconda3/envs/transformer_env/lib/python3.11/site-packages/urllib3/connectionpool.py", line 843, in urlopen
    retries = retries.increment(
              ^^^^^^^^^^^^^^^^^^
  File "/home/zahemen/miniconda3/envs/transformer_env/lib/python3.11/site-packages/urllib3/util/retry.py", line 519, in increment
    raise MaxRetryError(_pool, url, reason) from reason  # type: ignore[arg-type]
    ^^^^^^^^^^^^^^^^^^^^^^^^^^^^^^^^^^^^^^^^^^^^^^^^^^^
urllib3.exceptions.MaxRetryError: HTTPSConnectionPool(host='api.wandb.ai', port=443): Max retries exceeded with url: /graphql (Caused by SSLError(SSLEOFError(8, '[SSL: UNEXPECTED_EOF_WHILE_READING] EOF occurred in violation of protocol (_ssl.c:1006)')))

During handling of the above exception, another exception occurred:

Traceback (most recent call last):
  File "/home/zahemen/miniconda3/envs/transformer_env/lib/python3.11/site-packages/wandb/sdk/lib/retry.py", line 131, in __call__
    result = self._call_fn(*args, **kwargs)
             ^^^^^^^^^^^^^^^^^^^^^^^^^^^^^^
  File "/home/zahemen/miniconda3/envs/transformer_env/lib/python3.11/site-packages/wandb/sdk/internal/internal_api.py", line 393, in execute
    return self.client.execute(*args, **kwargs)  # type: ignore
           ^^^^^^^^^^^^^^^^^^^^^^^^^^^^^^^^^^^^
  File "/home/zahemen/miniconda3/envs/transformer_env/lib/python3.11/site-packages/wandb/vendor/gql-0.2.0/wandb_gql/client.py", line 52, in execute
    result = self._get_result(document, *args, **kwargs)
             ^^^^^^^^^^^^^^^^^^^^^^^^^^^^^^^^^^^^^^^^^^^
  File "/home/zahemen/miniconda3/envs/transformer_env/lib/python3.11/site-packages/wandb/vendor/gql-0.2.0/wandb_gql/client.py", line 60, in _get_result
    return self.transport.execute(document, *args, **kwargs)
           ^^^^^^^^^^^^^^^^^^^^^^^^^^^^^^^^^^^^^^^^^^^^^^^^^
  File "/home/zahemen/miniconda3/envs/transformer_env/lib/python3.11/site-packages/wandb/sdk/lib/gql_request.py", line 58, in execute
    request = self.session.post(self.url, **post_args)
              ^^^^^^^^^^^^^^^^^^^^^^^^^^^^^^^^^^^^^^^^
  File "/home/zahemen/miniconda3/envs/transformer_env/lib/python3.11/site-packages/requests/sessions.py", line 637, in post
    return self.request("POST", url, data=data, json=json, **kwargs)
           ^^^^^^^^^^^^^^^^^^^^^^^^^^^^^^^^^^^^^^^^^^^^^^^^^^^^^^^^^
  File "/home/zahemen/miniconda3/envs/transformer_env/lib/python3.11/site-packages/requests/sessions.py", line 589, in request
    resp = self.send(prep, **send_kwargs)
           ^^^^^^^^^^^^^^^^^^^^^^^^^^^^^^
  File "/home/zahemen/miniconda3/envs/transformer_env/lib/python3.11/site-packages/requests/sessions.py", line 703, in send
    r = adapter.send(request, **kwargs)
        ^^^^^^^^^^^^^^^^^^^^^^^^^^^^^^^
  File "/home/zahemen/miniconda3/envs/transformer_env/lib/python3.11/site-packages/requests/adapters.py", line 698, in send
    raise SSLError(e, request=request)
requests.exceptions.SSLError: HTTPSConnectionPool(host='api.wandb.ai', port=443): Max retries exceeded with url: /graphql (Caused by SSLError(SSLEOFError(8, '[SSL: UNEXPECTED_EOF_WHILE_READING] EOF occurred in violation of protocol (_ssl.c:1006)')))
2024-12-28 20:26:30,375 ERROR   MainThread:90855 [wandb_init.py:init():849] encountered error: Run initialization has timed out after 90.0 sec. Please try increasing the timeout with the `init_timeout` setting: `wandb.init(settings=wandb.Settings(init_timeout=120))`.
2024-12-28 20:26:30,375 ERROR   MainThread:90855 [wandb_init.py:init():1308] error in wandb.init()
Traceback (most recent call last):
  File "/home/zahemen/miniconda3/envs/transformer_env/lib/python3.11/site-packages/wandb/sdk/wandb_init.py", line 1298, in init
    return wi.init()
           ^^^^^^^^^
  File "/home/zahemen/miniconda3/envs/transformer_env/lib/python3.11/site-packages/wandb/sdk/wandb_init.py", line 855, in init
    raise error
wandb.errors.errors.CommError: Run initialization has timed out after 90.0 sec. Please try increasing the timeout with the `init_timeout` setting: `wandb.init(settings=wandb.Settings(init_timeout=120))`.
2024-12-28 20:26:30,385 WARNING MsgRouterThr:90855 [router.py:message_loop():75] message_loop has been closed
