2025-01-07 11:02:41,318 INFO    MainThread:84399 [wandb_setup.py:_flush():68] Current SDK version is 0.19.1
2025-01-07 11:02:41,318 INFO    MainThread:84399 [wandb_setup.py:_flush():68] Configure stats pid to 84399
2025-01-07 11:02:41,318 INFO    MainThread:84399 [wandb_setup.py:_flush():68] Loading settings from /home/zahemen/.config/wandb/settings
2025-01-07 11:02:41,318 INFO    MainThread:84399 [wandb_setup.py:_flush():68] Loading settings from /home/zahemen/projects/dl-lib/DocAnalyzerAI/wandb/settings
2025-01-07 11:02:41,318 INFO    MainThread:84399 [wandb_setup.py:_flush():68] Loading settings from environment variables
2025-01-07 11:02:41,318 INFO    MainThread:84399 [wandb_init.py:_log_setup():528] Logging user logs to /home/zahemen/projects/dl-lib/DocAnalyzerAI/wandb/run-20250107_110241-pggmvk79/logs/debug.log
2025-01-07 11:02:41,318 INFO    MainThread:84399 [wandb_init.py:_log_setup():529] Logging internal logs to /home/zahemen/projects/dl-lib/DocAnalyzerAI/wandb/run-20250107_110241-pggmvk79/logs/debug-internal.log
2025-01-07 11:02:41,318 INFO    MainThread:84399 [wandb_init.py:init():644] calling init triggers
2025-01-07 11:02:41,318 INFO    MainThread:84399 [wandb_init.py:init():650] wandb.init called with sweep_config: {}
config: {}
2025-01-07 11:02:41,318 INFO    MainThread:84399 [wandb_init.py:init():680] starting backend
2025-01-07 11:02:41,318 INFO    MainThread:84399 [wandb_init.py:init():684] sending inform_init request
2025-01-07 11:02:41,322 INFO    MainThread:84399 [backend.py:_multiprocessing_setup():104] multiprocessing start_methods=fork,spawn,forkserver, using: spawn
2025-01-07 11:02:41,322 INFO    MainThread:84399 [wandb_init.py:init():697] backend started and connected
2025-01-07 11:02:41,323 INFO    MainThread:84399 [wandb_init.py:init():790] updated telemetry
2025-01-07 11:02:41,326 INFO    MainThread:84399 [wandb_init.py:init():822] communicating run to backend with 90.0 second timeout
2025-01-07 11:03:09,485 INFO    Thread-2 (wrapped_target):84399 [retry.py:__call__():172] Retry attempt failed:
Traceback (most recent call last):
  File "/home/zahemen/miniconda3/envs/transformer_LM/lib/python3.11/site-packages/urllib3/connection.py", line 199, in _new_conn
    sock = connection.create_connection(
           ^^^^^^^^^^^^^^^^^^^^^^^^^^^^^
  File "/home/zahemen/miniconda3/envs/transformer_LM/lib/python3.11/site-packages/urllib3/util/connection.py", line 60, in create_connection
    for res in socket.getaddrinfo(host, port, family, socket.SOCK_STREAM):
               ^^^^^^^^^^^^^^^^^^^^^^^^^^^^^^^^^^^^^^^^^^^^^^^^^^^^^^^^^^
  File "/home/zahemen/miniconda3/envs/transformer_LM/lib/python3.11/socket.py", line 974, in getaddrinfo
    for res in _socket.getaddrinfo(host, port, family, type, proto, flags):
               ^^^^^^^^^^^^^^^^^^^^^^^^^^^^^^^^^^^^^^^^^^^^^^^^^^^^^^^^^^^
socket.gaierror: [Errno -3] Temporary failure in name resolution

The above exception was the direct cause of the following exception:

Traceback (most recent call last):
  File "/home/zahemen/miniconda3/envs/transformer_LM/lib/python3.11/site-packages/urllib3/connectionpool.py", line 789, in urlopen
    response = self._make_request(
               ^^^^^^^^^^^^^^^^^^^
  File "/home/zahemen/miniconda3/envs/transformer_LM/lib/python3.11/site-packages/urllib3/connectionpool.py", line 490, in _make_request
    raise new_e
  File "/home/zahemen/miniconda3/envs/transformer_LM/lib/python3.11/site-packages/urllib3/connectionpool.py", line 466, in _make_request
    self._validate_conn(conn)
  File "/home/zahemen/miniconda3/envs/transformer_LM/lib/python3.11/site-packages/urllib3/connectionpool.py", line 1095, in _validate_conn
    conn.connect()
  File "/home/zahemen/miniconda3/envs/transformer_LM/lib/python3.11/site-packages/urllib3/connection.py", line 693, in connect
    self.sock = sock = self._new_conn()
                       ^^^^^^^^^^^^^^^^
  File "/home/zahemen/miniconda3/envs/transformer_LM/lib/python3.11/site-packages/urllib3/connection.py", line 206, in _new_conn
    raise NameResolutionError(self.host, self, e) from e
urllib3.exceptions.NameResolutionError: <urllib3.connection.HTTPSConnection object at 0x7fc6d4e69e50>: Failed to resolve 'api.wandb.ai' ([Errno -3] Temporary failure in name resolution)

The above exception was the direct cause of the following exception:

Traceback (most recent call last):
  File "/home/zahemen/miniconda3/envs/transformer_LM/lib/python3.11/site-packages/requests/adapters.py", line 667, in send
    resp = conn.urlopen(
           ^^^^^^^^^^^^^
  File "/home/zahemen/miniconda3/envs/transformer_LM/lib/python3.11/site-packages/urllib3/connectionpool.py", line 843, in urlopen
    retries = retries.increment(
              ^^^^^^^^^^^^^^^^^^
  File "/home/zahemen/miniconda3/envs/transformer_LM/lib/python3.11/site-packages/urllib3/util/retry.py", line 519, in increment
    raise MaxRetryError(_pool, url, reason) from reason  # type: ignore[arg-type]
    ^^^^^^^^^^^^^^^^^^^^^^^^^^^^^^^^^^^^^^^^^^^^^^^^^^^
urllib3.exceptions.MaxRetryError: HTTPSConnectionPool(host='api.wandb.ai', port=443): Max retries exceeded with url: /graphql (Caused by NameResolutionError("<urllib3.connection.HTTPSConnection object at 0x7fc6d4e69e50>: Failed to resolve 'api.wandb.ai' ([Errno -3] Temporary failure in name resolution)"))

During handling of the above exception, another exception occurred:

Traceback (most recent call last):
  File "/home/zahemen/miniconda3/envs/transformer_LM/lib/python3.11/site-packages/wandb/sdk/lib/retry.py", line 131, in __call__
    result = self._call_fn(*args, **kwargs)
             ^^^^^^^^^^^^^^^^^^^^^^^^^^^^^^
  File "/home/zahemen/miniconda3/envs/transformer_LM/lib/python3.11/site-packages/wandb/sdk/internal/internal_api.py", line 393, in execute
    return self.client.execute(*args, **kwargs)  # type: ignore
           ^^^^^^^^^^^^^^^^^^^^^^^^^^^^^^^^^^^^
  File "/home/zahemen/miniconda3/envs/transformer_LM/lib/python3.11/site-packages/wandb/vendor/gql-0.2.0/wandb_gql/client.py", line 52, in execute
    result = self._get_result(document, *args, **kwargs)
             ^^^^^^^^^^^^^^^^^^^^^^^^^^^^^^^^^^^^^^^^^^^
  File "/home/zahemen/miniconda3/envs/transformer_LM/lib/python3.11/site-packages/wandb/vendor/gql-0.2.0/wandb_gql/client.py", line 60, in _get_result
    return self.transport.execute(document, *args, **kwargs)
           ^^^^^^^^^^^^^^^^^^^^^^^^^^^^^^^^^^^^^^^^^^^^^^^^^
  File "/home/zahemen/miniconda3/envs/transformer_LM/lib/python3.11/site-packages/wandb/sdk/lib/gql_request.py", line 58, in execute
    request = self.session.post(self.url, **post_args)
              ^^^^^^^^^^^^^^^^^^^^^^^^^^^^^^^^^^^^^^^^
  File "/home/zahemen/miniconda3/envs/transformer_LM/lib/python3.11/site-packages/requests/sessions.py", line 637, in post
    return self.request("POST", url, data=data, json=json, **kwargs)
           ^^^^^^^^^^^^^^^^^^^^^^^^^^^^^^^^^^^^^^^^^^^^^^^^^^^^^^^^^
  File "/home/zahemen/miniconda3/envs/transformer_LM/lib/python3.11/site-packages/requests/sessions.py", line 589, in request
    resp = self.send(prep, **send_kwargs)
           ^^^^^^^^^^^^^^^^^^^^^^^^^^^^^^
  File "/home/zahemen/miniconda3/envs/transformer_LM/lib/python3.11/site-packages/requests/sessions.py", line 703, in send
    r = adapter.send(request, **kwargs)
        ^^^^^^^^^^^^^^^^^^^^^^^^^^^^^^^
  File "/home/zahemen/miniconda3/envs/transformer_LM/lib/python3.11/site-packages/requests/adapters.py", line 700, in send
    raise ConnectionError(e, request=request)
requests.exceptions.ConnectionError: HTTPSConnectionPool(host='api.wandb.ai', port=443): Max retries exceeded with url: /graphql (Caused by NameResolutionError("<urllib3.connection.HTTPSConnection object at 0x7fc6d4e69e50>: Failed to resolve 'api.wandb.ai' ([Errno -3] Temporary failure in name resolution)"))
2025-01-07 11:04:11,353 ERROR   MainThread:84399 [wandb_init.py:init():849] encountered error: Run initialization has timed out after 90.0 sec. Please try increasing the timeout with the `init_timeout` setting: `wandb.init(settings=wandb.Settings(init_timeout=120))`.
2025-01-07 11:04:11,354 ERROR   MainThread:84399 [wandb_init.py:init():1308] error in wandb.init()
Traceback (most recent call last):
  File "/home/zahemen/miniconda3/envs/transformer_LM/lib/python3.11/site-packages/wandb/sdk/wandb_init.py", line 1298, in init
    return wi.init()
           ^^^^^^^^^
  File "/home/zahemen/miniconda3/envs/transformer_LM/lib/python3.11/site-packages/wandb/sdk/wandb_init.py", line 855, in init
    raise error
wandb.errors.errors.CommError: Run initialization has timed out after 90.0 sec. Please try increasing the timeout with the `init_timeout` setting: `wandb.init(settings=wandb.Settings(init_timeout=120))`.
2025-01-07 11:04:11,530 WARNING MsgRouterThr:84399 [router.py:message_loop():75] message_loop has been closed
